Workbook

Sheet 📊ダッシュボード
A1: 🏢 不動産査定管理システム v18.2.4
A2: 更新: 2025-11-26 | 次回OCRリセット: 2025-12-01
B4: 📊 物件 | H4: 🏢 業者 | N4: ⚠️ 注意 | T4: 📈 査定
A5: =COUNTA('📋査定物件詳細'!B5:B1000) -> 4 | F5: =COUNTA('🏢業者情報管理'!B5:B1000) -> 12 | N5: =COUNTA('⚠️査定時の注意事項'!B5:B1000) -> 9 | T5: =COUNTA('査定結果入力'!B5:B1000) -> 13
B6: 管理中 | H6: 提携 | N6: 要監視 | T6: 今月
B7: 📊 月間推移 (直近6ヶ月) | F7: 提携業者 ↗ | J7: 数 | N7: 要監視 ⚡ | T7: アクティブ 🚀
I8: 業者ランク
E9: 新規 | I9: ランク
E10: =COUNTIFS('査定結果入力'!D:D,"2025-08",'査定結果入力'!F:F,"新規") -> 0 | I10: S
E11: =COUNTIFS('査定結果入力'!D:D,"2025-09",'査定結果入力'!F:F,"新規") -> 0 | I11: A
A12: 2025-10
A13: 2025-11
B14: 2025年7月
A15: 2025年8月 | E15: 1 | F15: =D15/C15 -> #DIV/0! | G15: 2,510万円 | I15: B級 | J15: =COUNTIF('🏢業者情報管理'!H7:H1000,"B") -> 3
B16: 2025年9月 | C16: 14 | D16: 9 | E16: 2 | F16: =D16/C16 -> 0.64285714 | G16: 2,350万円
A17: 2025年10月
B18: 2025年11月 | C18: 20 | D18: 15 | E18: 4 | F18: =D18/C18 -> 0.75 | G18: 2,530万円
B29: =CONCATENATE("🔍 OCR: ",'📸OCR機能セットアップ'!B358,"/1000回 (残り",'📸OCR機能セットアップ'!D355,")") -> 🔍 OCR: /1000回 (残り)
B30: =IF('📸OCR機能セットアップ'!D355>500,"🟢 余裕あり",IF('📸OCR機能セットアップ'!D355>200,"🟡 注意","🔴 残り少ない")) -> 🔴 残り少ない
B32: 🔗 クイックアクセス
B33: 📋 物件詳細 | G33: 📊 比較分析 | L33: 📝 査定入力 | Q33: 🏢 業者管理
B36: ⚠️ 注意事項 | G36: 📸 OCR設定 | L36: 📖 使い方 | Q36: 🔧 システム
B40: System v18.2.4 | 8 Sheets | 🟢 Production Ready
B41: Last Update: 2025-11-26

Sheet 使い方ガイド
A1: 📖 OCR機能 完全利用ガイド
A2: Real Estate Appraisal Management System - Complete OCR Guide
A3: v18.2.4 | 最終更新: 2025-11-26
A5: 📑 目次
A6: STEP 1: 初期セットアップ（GCPアカウント・API有効化・APIキー作成）
A7: STEP 2: OCR実行方法（画像準備・実行手順・⚠️使用回数の自動更新）
A8: STEP 3: 使用回数管理（自動更新・残回数確認）
A9: STEP 4: 月次リセット（毎月1日作業）
A10: 重要な注意事項・トラブルシューティング
A11: STEP 5: データバックアップ
A15: 1️⃣ STEP 1: 初期セットアップ
A17: ① Google Cloud Platform (GCP) アカウント作成 | B17: Google Cloud Platform（GCP）アカウント作成
A18: 1. https://console.cloud.google.com にアクセス | B18: GCPコンソール(cloud.google.com)にアクセス → アカウント作成 → クレジットカード登録（月1,000回まで無料） → プロジェクト作成
A19: 2. Googleアカウントでログイン（既存のアカウントまたは新規作成） | B19: Cloud Vision API有効化
A20: 3. プロジェクトを作成（例: 「OCR-Project」） | B20: GCPコンソール → 「APIとサービス」 → 「ライブラリ」 → 「Cloud Vision API」検索 → 「有効にする」
A21: 1.3 | B21: APIキー作成
A22: ② Cloud Vision API の有効化 | B22: GCPコンソール → 「認証情報」 → 「認証情報を作成」 → 「APIキー」 → キーをコピー（セキュリティ推奨: Cloud Vision APIに制限）
A23: 1. GCPコンソール左上のメニュー > 「APIとサービス」 > 「ライブラリ」
A24: 2. 検索ボックスで「Vision API」を検索
A25: 3. 「Cloud Vision API」を選択し、「有効にする」をクリック
A27: ③ APIキーの作成 | B27: 物件画像ファイルの準備
A28: 1. 「APIとサービス」 > 「認証情報」をクリック | B28: 物件資料をスキャンまたは写真撮影 → Google DriveまたはWebにアップロード → 「リンクを知っている全員」に共有設定 → 画像URLをコピー
A29: 2. 「認証情報を作成」 > 「APIキー」を選択してキーを生成 | B29: OCR機能実行
A30: 3. 生成されたAPIキーをコピーし、「📸OCR機能セットアップ」シートのB4セルに貼り付け | B30: スプレッドシートのカスタムメニュー → 「OCR機能」 → 画像URLを入力 → 自動的に31項目が '📋査定物件詳細' シートに入力される
A31: ⚠️注意 | B31: OCR実行後は必ず使用回数を自動更新してください（STEP 3参照）
A32: 🔒 セキュリティ推奨設定
A33: APIキーに制限を設定してください：「APIの制限」で「Cloud Vision API」のみ許可することを推奨
A35: 2️⃣ STEP 2: OCR実行方法
A37: 📸 画像の準備 | B37: 使用回数の自動更新（最重要）
A38: 1. JPEGまたはPNG形式の画像を用意（登記簿や査定書類など） | B38: OCR実行後、'📸OCR機能セットアップ' シートのセルB358を +1 更新（例: 0 → 1 → 2...）
A39: 2. 画像ファイルサイズは10MB以下を推奨 | B39: 残り回数の確認
A40: 3. 画像は明るく、文字がはっきり読める状態にしてください | B40: '📊ダッシュボード' シートで「残り回数」と「ステータス」を確認（リアルタイム自動計算）
A41: ⚠️重要 | B41: 使用回数の更新忘れは料金超過の原因になります。OCR実行直後に必ず更新してください。
A42: ▶️ OCR機能の実行手順
A43: 1. 「📸OCR機能セットアップ」シートを開く
A44: 2. 画像をシート内の指定エリアに配置
A45: 3. OCR実行ボタンをクリック（自動でテキスト抽出開始）
A47: ⚠️ 重要: 使用回数の自動更新 | B47: 毎月1日の必須作業
A48: OCR実行後、必ず「📸OCR機能セットアップ」シートのセルB358の使用回数を自動的に更新されます。 | B48: 毎月1日に '📸OCR機能セットアップ' シートのセルB358を「0」にリセット（無料枠が1,000回に戻ります）
A49: 例: OCR実行前にB358が「5」の場合、実行後は「6」に更新 | B49: ダッシュボードで確認
...

Sheet 🏢業者情報管理
A1: 🏢 業者情報管理マスター
A2: ← ダッシュボードに戻る
A4: 最終更新日 | B4: =TODAY() -> 45992
A6: 業者No. | B6: 業者名 | C6: 電話番号 | D6: メールアドレス | E6: 住所 | F6: 営業時間 | G6: 担当者名 | H6: 推奨ランク | I6: 査定実績件数 | J6: 平均対応日数 | K6: 得意エリア | L6: 備考
A7: V001 | B7: 株式会社 GA technologis | C7: 080-8908-1616 | D7: g_fukasawa@ga-tech.co.jp | E7: 106-6290 東京都港区六本木3-2-1 住友不動産六本木グランドタワー 40F | F7: 平日 9:00-18:00 | G7: 深澤様 | H7: S | J7: 2.3 | K7: 東京23区全域・全国対応 | L7: 特徴：日本一の買取再販業社。サブ継承も可能。メモ：取引NG業社や賃貸先がアンビションはNG
A8: V002 | B8: イリス管財株式会社 | C8: 080-6574-2445 | D8: j.chikyu@iriskanzai.co.jp | E8: 170-0013 東京都豊島区東池袋2-44-1 小林ビル2階 | F8: 平日 9:00-19:00 | G8: 知久様 | H8: A | J8: 3.1 | K8: 東京・神奈川 | L8: 特徴：イオン住とSBJ提携の為、表面賃料が高い物件や精神的瑕疵などに強み、レスポンス遅め。メモ：役員が郷之丸さんの知人
A9: V003 | B9: GATES株式会社 | C9: LINE連絡 | D9: info@gates.co.jp | E9: 160-6134 東京都新宿区西新宿8-17-1 住友不動産新宿グランドタワー34階 | F9: 平日 9:30-18:30 | G9: 中島専務 or 平井様 | H9: A | J9: 2.8 | K9: 東京・埼玉・千葉 | L9: 特徴：物上げもやるが買取再販もOK。アパート用地も2026年から本格的に買取して、年間20棟位の建築をスタート予定。メモ：西田会長が顧問している会社。旧セルゲートジャパン。
A10: V004 | B10: 株式会社アセットジャパン | C10: 080-4324-8280 | D10: tateno@assetjapan.co.jp | E10: 104-0045 東京都中央区築地7-12-7 築地FTSビル3F | F10: 平日 10:00-19:00 | G10: 木村部長・舘野様 | H10: B | J10: 4.2 | K10: 都内・大阪エリアのみ | L10: 特徴：ジャックスオンリーでコンパクトな築浅が得意。サブ継承はやらない。都内と大阪エリアのみ。
A11: V005 | B11: 株式会社エーシークリエイト | C11: 090-2142-9627 | D11: iijima@ac-create.jp | E11: 151-0053 東京都渋谷区代々木2-10-8 ケイアイ新宿ビル6階 | F11: 平日 9:00-18:00 | G11: 飯島専務 | H11: B | J11: 3.5 | K11: 東京・神奈川 | L11: 特徴：SBJ提携業社で評価高め。サブ継承も可能。
A12: V006 | B12: 株式会社ランドネット | C12: 03-3986-3601 | D12: tamura-hi@landnet.co.jp | E12: 171-0022 東京都豊島区南池袋1-16-15 ダイヤゲート池袋7F | F12: 平日 9:00-18:00 | G12: 田村 鴻人（主任） | H12: B | J12: 0 | K12: 東京・埼玉 | L12: 第1営業部1課・主任 / Mobile: 090-1992-1967 / Fax: 03-3986-3979 / URL: http://landnet.co.jp/
A14: 📊 業者情報サマリー
A16: 登録業者数 | B16: =COUNTA(B7:B12)&"社" -> 6社
A17: 推奨ランクS | B17: =COUNTIF(H7:H1000,"S")&" 社" -> 1 社
A18: 推奨ランクA | B18: =COUNTIF(H7:H1000,"A")&" 社" -> 2 社
A19: 推奨ランクB | B19: =COUNTIF(H7:H1000,"B")&" 社" -> 3 社
A20: 平均対応日数 | B20: =TEXT(AVERAGE(J7:J1000),"0.0")&" 日" -> 2.7 日
A23: • 業者情報は月次で更新することを推奨します
A24: • 推奨ランクは査定実績、対応速度、評価に基づいて設定してください
A25: • 新規業者は必ず「⚠️査定時の注意事項」シートで確認してください
A26: • 連絡先変更時は速やかに更新してください
A27: 📌 重要な注意事項
A29: システムバージョン: v18.2.4 | 最終更新: 2025-11-26

Sheet ⚠️査定時の注意事項
A1: ⚠️ 査定時の注意事項管理
A3: 🚨 このシートは機密情報です 査定前に必ず確認し、注意レベル「高」の業者は回避してください
A6: No. | B6: 正式社名 | C6: 通称 | D6: 設立年 | E6: 宅建業免許番号 | F6: 本店所在地 | G6: 注意レベル | H6: 備考
A7: 1 | B7: NITOH株式会社 | C7: ニトウ | D7: 2006年（平成18年） | E7: 東京都知事（4）第86265号 | F7: 東京都新宿区西新宿1-25-1 新宿センタービル 32階 | G7: 高 | H7: 買取業者として要注意
A8: 2 | B8: ダーウィンアセットパートナーズ株式会社 | C8: ダーウィン | D8: 2009年9月18日 | E8: 国土交通大臣（1）第10526号 | F8: 東京都港区南青山1-1-1 新青山ビル東館 3F | G8: 高 | H8: 取引条件に注意
A9: 3 | B9: 株式会社Asucre Partners | C9: アスクルパートナーズ | D9: 2012年3月 | E9: 国土交通大臣（1）第10474号 | F9: 東京都渋谷区桜丘町20-1 渋谷インフォスタワー 18F | G9: 高 | H9: 契約内容確認必須
A10: 4 | B10: 株式会社ベルテックス | C10: ヴェルテックス | D10: 2010年12月7日 | E10: 国土交通大臣（1）第9910号 | F10: 東京都新宿区西新宿6-8-1 住友不動産新宿オークタワー 9階 | G10: 高 | H10: 査定額に注意
A11: 5 | B11: 株式会社アセットリード | C11: アセットリード | D11: 2000年3月27日 | E11: 東京都知事（5）第79542号 | F11: 東京都新宿区西新宿1-26-2 新宿野村ビル 26階 | G11: 高 | H11: 対応に注意
A12: 6 | B12: 大和インフィリンク株式会社 | C12: 大和インフィリンク | D12: 2015年11月13日 | E12: 国土交通大臣（1）第10398号 | F12: 東京都新宿区新宿4-3-17 FORECAST新宿SOUTH 4階 | G12: 高 | H12: 契約条件確認必須
A13: 7 | B13: SUNKASE株式会社 | C13: サンカセ | D13: 2018年8月24日 | E13: 東京都知事（1）第105944号 | F13: 東京都渋谷区南平台町2-12 渋谷南平台ビル 6階 | G13: 高 | H13: 取引実績要確認
A14: 8 | B14: 株式会社スタイルアジアンインベスター | C14: スタイルアジアン | D14: 2019年1月11日 | E14: 大阪府知事（2）第60908号 | F14: 大阪府大阪市西区北堀江2-4-11 サンライズビル 2F / 5F | G14: 高 | H14: 大阪拠点、要注意
A16: 📊 注意レベル「高」: 8社 | 総NG業者: 8社 | 最終更新: 2025-11-27

Sheet 査定結果入力
A1: 📋 査定結果入力シート
A3: ← ダッシュボードに戻る
A4: 入力日： | B4: =TODAY() -> 45992
A6: 📌 査定対象物件： | B6: ブライズ品川南ル・リオン1402号室
A7: 💡 物件選択：📋査定物件詳細シートで物件を選択すると、自動的に反映されます
A9: 業者名 | B9: 査定額（万円） | C9: 査定日 | D9: 対応日数 | E9: コメント・備考 | F9: ランキング
A10: エーシークリエイト | B10: 2150 | C10: =TODAY() -> 45992 | D10: 3 | E10: 仲介手数料込 | F10: 1 | AA10: =AND(B10<>"",B10=MAX($B$10:$B$19),MAX($B$10:$B$19)>0) -> TRUE | AB10: =AND(B10<>"",B10=MIN($B$10:$B$19),COUNTIF($B$10:$B$19,">0")>1) -> FALSE
A11: GATES | B11: 2070 | C11: =TODAY() -> 45992 | D11: 3 | F11: 3 | AA11: =AND(B11<>"",B11=MAX($B$10:$B$19),MAX($B$10:$B$19)>0) -> FALSE | AB11: =AND(B11<>"",B11=MIN($B$10:$B$19),COUNTIF($B$10:$B$19,">0")>1) -> FALSE
A12: GA technologis | B12: 0 | E12: 取扱不可 | AA12: =AND(B12<>"",B12=MAX($B$10:$B$19),MAX($B$10:$B$19)>0) -> FALSE | AB12: =AND(B12<>"",B12=MIN($B$10:$B$19),COUNTIF($B$10:$B$19,">0")>1) -> TRUE
A13: アセットジャパン | B13: 0 | E13: 取扱不可 | F13: 2 | AA13: =AND(B13<>"",B13=MAX($B$10:$B$19),MAX($B$10:$B$19)>0) -> FALSE | AB13: =AND(B13<>"",B13=MIN($B$10:$B$19),COUNTIF($B$10:$B$19,">0")>1) -> TRUE
A14: イリス管財 | B14: 0 | E14: 取扱不可 | F14: 2 | AA14: =AND(B14<>"",B14=MAX($B$10:$B$19),MAX($B$10:$B$19)>0) -> FALSE | AB14: =AND(B14<>"",B14=MIN($B$10:$B$19),COUNTIF($B$10:$B$19,">0")>1) -> TRUE
F15: =IF(B15="","",IF(B15=0,"",COUNTIFS($B$10:$B$29,">"&B15,$B$10:$B$29,"<>",$B$10:$B$29,"<>0")+1)) | AA15: =AND(B15<>"",B15=MAX($B$10:$B$19),MAX($B$10:$B$19)>0) -> FALSE | AB15: =AND(B15<>"",B15=MIN($B$10:$B$19),COUNTIF($B$10:$B$19,">0")>1) -> FALSE
F16: =IF(B16="","",IF(B16=0,"",COUNTIFS($B$10:$B$29,">"&B16,$B$10:$B$29,"<>",$B$10:$B$29,"<>0")+1)) | AA16: =AND(B16<>"",B16=MAX($B$10:$B$19),MAX($B$10:$B$19)>0) -> FALSE | AB16: =AND(B16<>"",B16=MIN($B$10:$B$19),COUNTIF($B$10:$B$19,">0")>1) -> FALSE
F17: =IF(B17="","",IF(B17=0,"",COUNTIFS($B$10:$B$29,">"&B17,$B$10:$B$29,"<>",$B$10:$B$29,"<>0")+1)) | AA17: =AND(B17<>"",B17=MAX($B$10:$B$19),MAX($B$10:$B$19)>0) -> FALSE | AB17: =AND(B17<>"",B17=MIN($B$10:$B$19),COUNTIF($B$10:$B$19,">0")>1) -> FALSE
F18: =IF(B18="","",IF(B18=0,"",COUNTIFS($B$10:$B$29,">"&B18,$B$10:$B$29,"<>",$B$10:$B$29,"<>0")+1)) | AA18: =AND(B18<>"",B18=MAX($B$10:$B$19),MAX($B$10:$B$19)>0) -> FALSE | AB18: =AND(B18<>"",B18=MIN($B$10:$B$19),COUNTIF($B$10:$B$19,">0")>1) -> FALSE
F19: =IF(B19="","",IF(B19=0,"",COUNTIFS($B$10:$B$29,">"&B19,$B$10:$B$29,"<>",$B$10:$B$29,"<>0")+1)) | AA19: =AND(B19<>"",B19=MAX($B$10:$B$19),MAX($B$10:$B$19)>0) -> FALSE | AB19: =AND(B19<>"",B19=MIN($B$10:$B$19),COUNTIF($B$10:$B$19,">0")>1) -> FALSE
F20: =IF(B20="","",IF(B20=0,"",COUNTIFS($B$10:$B$29,">"&B20,$B$10:$B$29,"<>",$B$10:$B$29,"<>0")+1))
A21: 💡 注意：査定額の最高額は緑色、最低額は赤色で自動ハイライトされます（データ入力後に反映）
A22: 📊 査定結果サマリー
F23: =IF(B23="","",IF(B23=0,"",COUNTIFS($B$10:$B$29,">"&B23,$B$10:$B$29,"<>",$B$10:$B$29,"<>0")+1))
A24: 入力済み業者数： | B24: =COUNTA(A10:A19)&" 社" -> 5 社 | F24: =IF(B24="","",IF(B24=0,"",COUNTIFS($B$10:$B$29,">"&B24,$B$10:$B$29,"<>",$B$10:$B$29,"<>0")+1)) -> 2
A25: 最高査定額： | B25: =IF(COUNTIF(B10:B19,">0")=0,"未入力",TEXT(MAX(IFERROR(VALUE(B10:B19),0)),"#,##0")&"万円") -> 0万円 | F25: =IF(B25="","",IF(B25=0,"",COUNTIFS($B$10:$B$29,">"&B25,$B$10:$B$29,"<>",$B$10:$B$29,"<>0")+1)) -> 5
A26: 最低査定額： | B26: =IF(COUNTIF(B10:B19,">0")=0,"未入力",TEXT(MIN(IF(IFERROR(VALUE(B10:B19),0)>0,IFERROR(VALUE(B10:B19),0),999999)),"#,##0")&"万円") -> 999,999万円 | F26: =IF(B26="","",IF(B26=0,"",COUNTIFS($B$10:$B$29,">"&B26,$B$10:$B$29,"<>",$B$10:$B$29,"<>0")+1)) -> 1
A27: 平均査定額： | B27: =IF(COUNTIF(B10:B19,">0")=0,"未入力",TEXT(AVERAGEIF(B10:B19,">0"),"#,##0")&"万円") -> 2,110万円 | F27: =IF(B27="","",IF(B27=0,"",COUNTIFS($B$10:$B$29,">"&B27,$B$10:$B$29,"<>",$B$10:$B$29,"<>0")+1)) -> 4
A28: 査定額の差： | B28: =IF(COUNT(B10:B19)<2,"未入力",TEXT(AGGREGATE(4,6,B10:B19,1)-AGGREGATE(5,6,B10:B19,1),"#,##0")&"万円") -> #NAME? | F28: =IF(B28="","",IF(B28=0,"",COUNTIFS($B$10:$B$29,">"&B28,$B$10:$B$29,"<>",$B$10:$B$29,"<>0")+1)) -> #NAME?
A29: 平均対応日数： | B29: =IF(COUNTA(D10:D19)=0,"未入力",TEXT(AVERAGE(D10:D19),"0.0")&" 日") -> 3.0 日 | F29: =IF(B29="","",IF(B29=0,"",COUNTIFS($B$10:$B$29,">"&B29,$B$10:$B$29,"<>",$B$10:$B$29,"<>0")+1)) -> 3
A32: 📌 入力時の注意事項
A33: • 査定額は「万円」単位で入力してください（例：3,500万円 → 3500）
A34: • 業者名は🏢業者情報管理シートから選択することを推奨します
A35: • ⚠️査定時の注意事項シートで該当業者のリスク情報を必ず確認してください
A36: • ランキングは査定額の高い順に自動計算されます（1位が最高額）
A39: 📈 このシートのデータは「査定比較分析」シートのチャート連携に使用されます
A40: ※ 査定結果を入力すると、自動的にチャートが更新されます

Sheet 📋査定物件詳細
A1: 📋 査定物件詳細管理
A3: OCR機能を使用して物件情報を自動入力できます。査定物件の詳細データを一元管理し、比較分析に活用します。
A5: 📸 OCR機能クイックガイド（5ステップ）
A6: 📸 OCRクイックガイド（5ステップ）
A7: STEP 2: 物件資料（PDF、画像）をアップロード
A8: STEP 3: OCRボタンをクリックして自動抽出開始
A9: STEP 4: 抽出された情報を確認・修正
A10: STEP 5: このシートに自動反映（手動調整可能）
A11: 5️⃣ カウント更新: 📸OCR機能セットアップ シートのB358を +1 する（重要！）
A13: ✅ OCR使用回数は自動的に更新されます
A15: ━━━━━━━━━━━━━━━━━━━━━━━━━━━━━━━━━━━━━━━━━━━━━━━━━━━━━━━━━━━━━━━━━━━━━━━━━━━━━━━━━━━━━━━━━━
A17: 物件詳細データ（OCR自動入力エリア）
A20: 物件No. | B20: 物件名 | C20: 入力日 | D20: データソース | E20: 最寄り駅 | F20: 駅徒歩分 | G20: 現在の賃料 | H20: 管理費 | I20: 修繕積立金 | J20: マンション名 | K20: 所在地 | L20: 土地権利 | M20: 建ぺい率 | N20: 容積率 | O20: 用途地域 | P20: 建物構造 | Q20: 築年月 | R20: 総戸数 | S20: 所在階 | T20: 専有面積 | U20: バルコニー面積 | V20: 間取り | W20: 向き | X20: 管理形態 | Y20: 駐車場 | Z20: 現況 | AA20: 引渡時期 | AB20: 備考 | AC20: 追加情報1 | AD20: 追加情報2 | AE20: 追加情報3 | AF20: 追加情報4 | AG20: 備考
A21: P001 | B21: クレアシオン早稲田303号室 | C21: =TODAY() -> 45992 | E21: 早稲田駅 | F21: 5分 | G21: 東京都新宿区早稲田町 | H21: クレアシオン早稲田 | I21: RC造 | J21: 2015年3月 | K21: 50戸 | L21: 3階 | M21: 35.5㎡ | N21: 5.2㎡ | O21: 1LDK | P21: 南向き | Q21: 12.5万円 | R21: 8,000円 | S21: 5,000円 | T21: 所有権 | U21: 60% | V21: 200% | W21: 第一種住居地域 | X21: 委託管理 | Y21: 空き無し | Z21: 賃貸中 | AA21: 相談可 | AB21: 駅近好立地、学生需要高
A22: P002 | B22: ファーストフィオーレ神戸駅前 | C22: =TODAY() -> 45992 | E22: 神戸駅 | F22: 3分 | G22: 兵庫県神戸市中央区 | I22: SRC造 | J22: 2018年6月 | K22: 80戸 | L22: 5階 | M22: 42.8㎡ | N22: 6.5㎡ | O22: 1LDK | P22: 東向き | Q22: 9.8万円 | R22: 7,500円 | S22: 4,500円 | T22: 所有権 | U22: 80% | V22: 400% | W22: 商業地域 | X22: 委託管理 | Y22: 月額15,000円 | Z22: 賃貸中 | AA22: 即時可能 | AB22: 神戸駅至近、商業施設充実
A23: P003 | C23: =TODAY() -> 45992 | E23: 早稲田 | F23: 5 | G23: 26,500 | H23: なし | I23: なし | J23: クレアシオン早稲田 | K23: 東京都新宿区弁天町2-17 | L23: 所有権 | M23: 60% | N23: 300% | O23: 第一種住居地域 | P23: RC造地上10階建 | Q23: 平成14年4月 | R23: 28戸 | S23: 3階 | T23: 20.45㎡ | U23: バルコニー | V23: 1K | W23: 南 | X23: 全部委託 | Y23: あり | Z23: 空室 | AA23: 相談 | AB23: 日本フォルテ施工
A24: P004 | C24: =TODAY() -> 45992 | E24: 神戸 | F24: 5 | G24: 21,900 | H24: なし | I24: なし | K24: 兵庫県神戸市中央区相生町5-16-12 | L24: 所有権 | M24: 未記載 | N24: 未記載 | O24: 商業地域 | P24: RC造地上15階建 | Q24: 平成31年3月 | R24: 70戸 | S24: 未記載 | T24: 21.88㎡ | U24: バルコニー | V24: 1K | W24: 未記載 | X24: 全部委託 | Y24: あり | Z24: 賃貸中 | AA24: 相談 | AB24: 関電不動産開発施工
A25: P005 | B25: ブライズ品川南ル・リオン1402号室 | C25: =TODAY() -> 45992 | D25: 手動入力 | E25: 品川 | F25: 10 | G25: 8.9 | H25: 0.498 | I25: 0.598 | J25: ブライズ品川南ル・リオン | K25: 東京都品川区南大井4-11-7 | L25: 所有権 | M25: - | N25: - | O25: - | P25: RC | Q25: 2008年7月 | R25: 115 | S25: 14階 | T25: 22.98 | U25: - | V25: 1K | W25: - | X25: マスターリース契約 | Y25: なし | Z25: 賃貸中 | AA25: - | AB25: 管理会社：㈱イーリアルティ / マスターリース手数料：賃料の5%(4,450円) / 振込手数料：220円 / 修繕積立金改定予定：2026年2月より6,600円

Sheet 査定比較分析
A1: 📊 査定比較分析ダッシュボード
A3: このシートでは、査定結果入力シートに入力されたデータを自動的にグラフ化し、視覚的に比較分析します。
A5: 📈 査定額分析グラフ
A6: 📈 査定額分析グラフ
A7: 最高査定額・最低査定額・平均査定額を一目で比較できます。査定結果入力シートにデータを入力すると、自動的に更新されます。
A8: このセクションでは、「査定結果入力」シートのデータを基に、業者別の査定額をグラフで比較できます。
A12: グラフエリア →
A13: このグラフは「査定結果入力」シートのデータを自動的にグラフ化します
A16: 📝 使い方
A17: 💡 使い方
A18: 1. 「査定結果入力」シートで業者ごとの査定額を入力すると自動的に分析されます
A19: 2. このシートに戻ると、自動的にグラフが更新されます
A20: 3. グラフから業者間の査定額の違いを視覚的に確認できます

Sheet 📸OCR機能セットアップ
A1: 📸 OCR機能セットアップ - 完全ガイド
A3: このシートには、OCR機能を使用するために必要なすべての情報が含まれています。
A4: 以下のセクションを順番に進めてください。
A5: 📑 目次
A6: 📖 目次（クイックナビゲーション）
A7: 1️⃣ 初期セットアップガイド（A10～）
A8: 2️⃣ Apps Scriptコード（A60～）
A9: 3️⃣ 使用回数カウンター（A160～）
A10: 4️⃣ トラブルシューティング（A210～）
A12: ━━━━━━━━━━━━━━━━━━━━━━━━━━━━━━━━━━━━━━
A13: 1️⃣ 初期セットアップガイド
A16: 【ステップ1】Google Cloud Platformアカウント作成
... A67: // ============================================ // 不動産査定管理システム - OCR機能 // Google Cloud Vision API連携コード // バージョン: v18.2.4 完全修正版 // 最終更新: 2025-11-25 // ============================================ // ⚠️ 重要: 下記のYOUR_API_KEYを実際のGoogle Cloud Vision APIキーに置き換えてください const API_KEY = 'YOUR_GOOGLE_CLOUD_VISION_API_KEY_HERE'; /** * スプレッドシート起動時にカスタムメニューを追加 */ function onOpen() { try { const ui = SpreadsheetApp.getUi(); ui.createMenu('🔍 OCR機能') .addItem('📸 物件画像から情報抽出', 'extractPropertyInfo') .addToUi(); } catch (error) { Logger.log('onOpen Error: ' + error.message); } } /** * メイン処理: 物件情報の抽出 */ function extractPropertyInfo() { let ui; try { ui = SpreadsheetApp.getUi(); } catch (error) { Logger.log('UI取得エラー: ' + error.message); return; } // 画像URLの入力 const response = ui.prompt( '📸 画像URL入力', '物件情報が記載された画像のURLを入力してください:\n(Google DriveまたはWeb上の画像)', ui.ButtonSet.OK_CANCEL ); if (response.getSelectedButton() !== ui.Button.OK) { return; } const imageUrl = response.getResponseText().trim(); if (!imageUrl) { ui.alert('⚠️ エラー', '画像URLが入力されていません。', ui.ButtonSet.OK); return; } try { // Vision APIでテキスト抽出 ui.alert('処理中', 'Google Cloud Vision APIでテキストを抽出しています...', ui.ButtonSet.OK); const extractedText = callVisionAPI(imageUrl); // テキストから物件データをパース const propertyData = parsePropertyData(extractedText); // データをシートに書き込み const propertyNo = writeToSheet(propertyData); ui.alert( '✅ 完了', '物件情報を「📋査定物件詳細」シートに登録しました。\n\n' + '物件No: ' + propertyNo + '\n' + '入力項目数: 31項目\n\n' + '⚠️ 重要: 📸OCR機能セットアップシートのB358セルを手動で+1してください', ui.ButtonSet.OK ); } catch (error) { ui.alert('❌ エラー', 'エラーが発生しました:\n' + error.message, ui.ButtonSet.OK); Logger.log('Error: ' + error.message); } } /** * Google Cloud Vision APIを呼び出してテキストを抽出 */ function callVisionAPI(imageUrl) { const visionUrl = 'https://vision.googleapis.com/v1/images:annotate?key=' + API_KEY; const payload = { requests: [{ image: { source: { imageUri: imageUrl } }, features: [{ type: 'TEXT_DETECTION', maxResults: 1 }] }] }; const options = { method: 'post', contentType: 'application/json', payload: JSON.stringify(payload), muteHttpExceptions: true }; const response = UrlFetchApp.fetch(visionUrl, options); const result = JSON.parse(response.getContentText()); if (result.responses && result.responses[0].textAnnotations) { return result.responses[0].textAnnotations[0].description; } throw new Error('画像からテキストを抽出できませんでした。画像URLと品質を確認してください。'); } /** * テキストから特定の値を抽出 */ function extractValue(text, pattern) { const match = text.match(pattern); return match ? match[1].trim() : ''; } /** * テキストから31項目の物件データをパース */ function parsePropertyData(text) { const data = { propertyName: extractValue(text, /物件名[:：]\s*(.+?)(?:\n|$)/i), nearestStation: extractValue(text, /最寄[り]?駅[:：]\s*(.+?)(?:\n|$)/i), walkMinutes: extractValue(text, /徒歩[:：]\s*(.+?)(?:分|$)/i), currentRent: extractValue(text, /賃料[:：]\s*(.+?)(?:円|$)/i), managementFee: extractValue(text, /管理費[:：]\s*(.+?)(?:円|$)/i), repairReserve: extractValue(text, /修繕積立金[:：]\s*(.+?)(?:円|$)/i), buildingName: extractValue(text, /建物名[:：]\s*(.+?)(?:\n|$)/i), address: extractValue(text, /所在地[:：]\s*(.+?)(?:\n|$)/i), landRights: extractValue(text, /土地権利[:：]\s*(.+?)(?:\n|$)/i), buildingCoverage: extractValue(text, /建[ぺ]?い率[:：]\s*(.+?)(?:%|$)/i), floorAreaRatio: extractValue(text, /容積率[:：]\s*(.+?)(?:%|$)/i), zoning: extractValue(text, /用途地域[:：]\s*(.+?)(?:\n|$)/i), buildingStructure: extractValue(text, /建物構造[:：]\s*(.+?)(?:\n|$)/i), constructionDate: extractValue(text, /建築年月[:：]\s*(.+?)(?:\n|$)/i), totalUnits: extractValue(text, /総戸数[:：]\s*(.+?)(?:戸|$)/i), floor: extractValue(text, /階数[:：]\s*(.+?)(?:階|$)/i), exclusiveArea: extractValue(text, /専有面積[:：]\s*(.+?)(?:㎡|m2|$)/i), balconyArea: extractValue(text, /バルコニー面積[:：]\s*(.+?)(?:㎡|m2|$)/i), layout: extractValue(text, /間取[り]?[:：]\s*(.+?)(?:\n|$)/i), orientation: extractValue(text, /方角[:：]\s*(.+?)(?:\n|$)/i), managementType: extractValue(text, /管理形態[:：]\s*(.+?)(?:\n|$)/i), parking: extractValue(text, /駐車場[:：]\s*(.+?)(?:\n|$)/i), currentStatus: extractValue(text, /現況[:：]\s*(.+?)(?:\n|$)/i), deliveryTime: extractValue(text, /引[き]?渡[し]?時期[:：]\s*(.+?)(?:\n|$)/i), remarks: extractValue(text, /備考[:：]\s*(.+?)(?:\n|$)/i), price: extractValue(text, /価格[:：]\s*(.+?)(?:円|万円|$)/i), transactionType: extractValue(text, /取引形態[:：]\s*(.+?)(?:\n|$)/i), ownership: extractValue(text, /所有権[:：]\s*(.+?)(?:\n|$)/i), equipmentFacilities: extractValue(text, /設備[・･]施設[:：]\s*(.+?)(?:\n|$)/i), renovationHistory: extractValue(text, /リフォーム履歴[:：]\s*(.+?)(?:\n|$)/i), previousUse: extractValue(text, /前回使用[:：]\s*(.+?)(?:\n|$)/i) }; return data; } /** * 抽出データを📋査定物件詳細シートに書き込み */ function writeToSheet(data) { const ss = SpreadsheetApp.getActiveSpreadsheet(); const targetSheet = ss.getSheetByName('📋査定物件詳細'); if (!targetSheet) { throw new Error('📋査定物件詳細シートが見つかりません'); } // 次の空行を検索 (21行目から開始) let nextRow = 21; while (targetSheet.getRange(nextRow, 1).getValue() !== '') { nextRow++; } // 物件番号を生成 const propertyNo = 'P' + String(nextRow - 20).padStart(4, '0'); // 現在の日付を取得 const today = new Date(); const dateStr = Utilities.formatDate(today, Session.getScriptTimeZone(), 'yyyy-MM-dd'); // データをA列からAG列（33列）に書き込み targetSheet.getRange(nextRow, 1).setValue(propertyNo); // A: 物件No. targetSheet.getRange(nextRow, 2).setValue(data.propertyName || ''); // B: 物件名 targetSheet.getRange(nextRow, 3).setValue(dateStr); // C: 入力日 targetSheet.getRange(nextRow, 4).setValue('OCR自動入力'); // D: データソース targetSheet.getRange(nextRow, 5).setValue(data.nearestStation || ''); // E: 最寄り駅 targetSheet.getRange(nextRow, 6).setValue(data.walkMinutes || ''); // F: 駅徒歩分 targetSheet.getRange(nextRow, 7).setValue(data.currentRent || ''); // G: 現在の賃料 targetSheet.getRange(nextRow, 8).setValue(data.managementFee || ''); // H: 管理費 targetSheet.getRange(nextRow, 9).setValue(data.repairReserve || ''); // I: 修繕積立金 targetSheet.getRange(nextRow, 10).setValue(data.buildingName || ''); // J: 建物名 targetSheet.getRange(nextRow, 11).setValue(data.address || ''); // K: 所在地 targetSheet.getRange(nextRow, 12).setValue(data.landRights || ''); // L: 土地権利 targetSheet.getRange(nextRow, 13).setValue(data.buildingCoverage || ''); // M: 建ぺい率 targetSheet.getRange(nextRow, 14).setValue(data.floorAreaRatio || ''); // N: 容積率 targetSheet.getRange(nextRow, 15).setValue(data.zoning || ''); // O: 用途地域 targetSheet.getRange(nextRow, 16).setValue(data.buildingStructure || ''); // P: 建物構造 targetSheet.getRange(nextRow, 17).setValue(data.constructionDate || ''); // Q: 建築年月 targetSheet.getRange(nextRow, 18).setValue(data.totalUnits || ''); // R: 総戸数 targetSheet.getRange(nextRow, 19).setValue(data.floor || ''); // S: 階数 targetSheet.getRange(nextRow, 20).setValue(data.exclusiveArea || ''); // T: 専有面積 targetSheet.getRange(nextRow, 21).setValue(data.balconyArea || ''); // U: バルコニー面積 targetSheet.getRange(nextRow, 22).setValue(data.layout || ''); // V: 間取り targetSheet.getRange(nextRow, 23).setValue(data.orientation || ''); // W: 方角 targetSheet.getRange(nextRow, 24).setValue(data.managementType || ''); // X: 管理形態 targetSheet.getRange(nextRow, 25).setValue(data.parking || ''); // Y: 駐車場 targetSheet.getRange(nextRow, 26).setValue(data.currentStatus || ''); // Z: 現況 targetSheet.getRange(nextRow, 27).setValue(data.deliveryTime || ''); // AA: 引渡時期 targetSheet.getRange(nextRow, 28).setValue(data.remarks || ''); // AB: 備考 targetSheet.getRange(nextRow, 29).setValue(data.price || ''); // AC: 価格 targetSheet.getRange(nextRow, 30).setValue(data.transactionType || ''); // AD: 取引形態 targetSheet.getRange(nextRow, 31).setValue(data.ownership || ''); // AE: 所有権 targetSheet.getRange(nextRow, 32).setValue(data.equipmentFacilities || ''); // AF: 設備・施設 targetSheet.getRange(nextRow, 33).setValue(data.renovationHistory || ''); // AG: リフォーム履歴 return propertyNo; }
C100: ='📸OCR機能セットアップ'!B352
C101: 1,000 回
C102: ='📸OCR機能セットアップ'!B358
C103: ='📸OCR機能セットアップ'!D355
C104: ='📸OCR機能セットアップ'!B360
A105: 📊 OCR使用回数トラッカー
A106: 対象月 | B106: =TEXT(TODAY(),"YYYY年MM月") -> 2025年12月 | C106: ※毎月1日に自動リセット
A107: 月間無料枠 | B107: 1,000回 | C107: 残り回数 | D107: =1000-B358 -> 1000
A108: 今月の使用回数 | B108: 100 | C108: 回 | D108: =B358/1000 -> 0
A109: ステータス | B109: =IF(D355>500,"✅ 十分な残り回数",IF(D355>200,"⚠️ 残り回数が減っています","🚨 残り回数が少なくなっています")) -> 🚨 残り回数が少なくなっています
A110: 💡 重要な注意事項
A111: • 1,000回を超えると課金が発生します（約$1.50/回） • 使用回数は手動で更新してください • 毎月1日にB358セルを「0」にリセットしてください • Google Cloud Platformの請求ダッシュボードで正確な使用状況を確認できます
A112: 🔒 セキュリティに関する重要な注意事項 | B112: リセット方法: セルB358を選択し「0」を入力 | C112: 月初リセットリマインダー
A113: ⚠️ APIキーの保護 | B113: Apps ScriptのAPIキーは機密情報です。第三者と共有しないでください。スプレッドシートを共有する際は、コードを削除するか、閲覧権限のみを付与してください。
A114: 💾 データバックアップ | B114: 定期的にスプレッドシートのコピーを作成し、Google Driveの別フォルダに保存してください。
A115: J
A116: K | B116: 駅徒歩分 | C116: 駅からの徒歩時間（分）
A117: L | B117: 現在の賃料 | C117: 現在設定されている家賃
A118: M | B118: 管理費 | C118: 月額管理費
A119: N | B119: 修繕積立金 | C119: 月額修繕積立金
A120: O | B120: 敷金預金額 | C120: 敷金または保証金
A121: P | B121: 管理体制 | C121: 管理方式（集金代行、サブリースなど）
A122: Q | B122: 賃貸管理会社名 | C122: 賃貸管理を行う会社
A123: R | B123: 建物管理会社名 | C123: 建物管理を行う会社
A124: S | B124: バルコニー面積 | C124: バルコニーの面積
A125: T | B125: 駐車場有無 | C125: 駐車場の有無
A126: U | B126: 駐車場料金 | C126: 駐車場の月額料金
...
